<?xml version='1.0' encoding='utf-8'?>
<robot xmlns:xacro="http://www.ros.org/wiki/xacro" name="sentinel">
    <!-- add more codes -->
    <link name="world"></link>
    <link name="base_link">
        <visual>
        <origin xyz="0.0 0.0 0.005"/>
            <geometry>
                <mesh filename="file:///$(find fra333_lab4_01_description)/mesh/base_link.STL"/>
            </geometry>
        </visual>
        <collision>
            <contact_coefficients mu="0" kp="1000.0" kd="1.0"/>
            <geometry>
                <mesh filename="file:///$(find fra333_lab4_01_description)/mesh/base_link.STL"/>
            </geometry>
        </collision>
        <inertial>
            <origin xyz="0.0 0.0 0.0" rpy="0.0 0.0 0.0"/>
            <mass value="1.0"/>
            <inertia ixx="0.0003890077" ixy="0.0" ixz="0.0" iyy="0.0003890077" iyz="0.0" izz="0.0005310862"/>
        </inertial>
    </link>
    <link name="link_0">
        <visual>
            <geometry>
                <mesh filename="file:///$(find fra333_lab4_01_description)/mesh/link_0.STL"/>
            </geometry>
        </visual>
        <collision>
            <contact_coefficients mu="0" kp="1000.0" kd="1.0"/>
            <geometry>
                <mesh filename="file:///$(find fra333_lab4_01_description)/mesh/link_0.STL"/>
            </geometry>
        </collision>
        <inertial>
            <origin xyz="0.0 0.0 0.0" rpy="0.0 0.0 0.0"/>
            <mass value="1.0"/>
            <inertia ixx="0.0003890077" ixy="0.0" ixz="0.0" iyy="0.0003890077" iyz="0.0" izz="0.0005310862"/>
        </inertial>
    </link>
    <link name="link_1">
        <visual>
            <geometry>
                <mesh filename="file:///$(find fra333_lab4_01_description)/mesh/link_1.STL"/>
            </geometry>
        </visual>
        <collision>
            <contact_coefficients mu="0" kp="1000.0" kd="1.0"/>
            <geometry>
                <mesh filename="file:///$(find fra333_lab4_01_description)/mesh/link_1.STL"/>
            </geometry>
        </collision>
        <inertial>
            <origin xyz="0.0 0.0 0.0" rpy="0.0 0.0 0.0"/>
            <mass value="2.13412"/>
            <inertia ixx="0.0092143483" ixy="0.0000029017" ixz="-0.0001157018" iyy="0.0099694985" iyz="-0.00000219019" izz="0.0021104429"/>
        </inertial>
    </link>
    <link name="link_2">
        <visual>
            <geometry>
                <mesh filename="file:///$(find fra333_lab4_01_description)/mesh/link_2.STL"/>
            </geometry>
        </visual>
        <collision>
            <contact_coefficients mu="0" kp="1000.0" kd="1.0"/>
            <geometry>
                <mesh filename="file:///$(find fra333_lab4_01_description)/mesh/link_2.STL"/>
            </geometry>
        </collision>
        <inertial>
            <origin xyz="0.0 0.0 0.0" rpy="0.0 0.0 0.0"/>
            <mass value="3.17536"/>
            <inertia ixx="0.0046929646" ixy="0.0" ixz="-0.007602469" iyy="0.196888" iyz="0.0" izz="0.195576"/>
        </inertial>
    </link>
    <link name="link_3">
        <visual>
            <geometry>
                <mesh filename="file:///$(find fra333_lab4_01_description)/mesh/link_3.STL"/>
            </geometry>
        </visual>
        <collision>
            <contact_coefficients mu="0" kp="1000.0" kd="1.0"/>
            <geometry>
                <mesh filename="file:///$(find fra333_lab4_01_description)/mesh/link_3.STL"/>
            </geometry>
        </collision>
        <inertial>
            <origin xyz="0.0 0.0 0.0" rpy="0.0 0.0 0.0"/>
            <mass value="3.38524"/>
            <inertia ixx="0.0029246047" ixy="0.00000000132" ixz="-0.00000704893" iyy="0.04357027" iyz="-0.00000000006" izz="0.04298572"/>
        </inertial>
    </link>
    <link name="gripper">
        <visual>
            <geometry>
                <mesh filename="file:///$(find fra333_lab4_01_description)/mesh/gripper.STL"/>
            </geometry>
        </visual>
        <collision>
            <contact_coefficients mu="0" kp="1000.0" kd="1.0"/>
            <geometry>
                <mesh filename="file:///$(find fra333_lab4_01_description)/mesh/gripper.STL"/>
            </geometry>
        </collision>
        <inertial>
            <origin xyz="0.0 0.0 0.0" rpy="0.0 0.0 0.0"/>
            <mass value="8.945"/>
            <inertia ixx="0.0000831101" ixy="0.0" ixz="0.0" iyy="0.0081156101" iyz="0.0" izz="0.00005080097"/>
        </inertial>
    </link>

    <joint name="base_link_to_world" type="fixed">
       <parent link="world"/>
       <child link="base_link"/>
       <origin xyz="0.0 0.0 0.035"/>
     </joint>

     <joint name="base_to_link_0" type="fixed">
       <parent link="base_link"/>
       <child link="link_0"/>
       <origin xyz="0.0 0.0 0.035"/>
     </joint>

     <joint name="link_0_to_1" type="revolute">
       <parent link="link_0"/>
       <child link="link_1"/>
       <origin xyz="0.0 0.0 0.045"/>
       <axis xyz="0.0 0.0 1.0"/>
       <limit lower="-3" upper="3" effort="100.0" velocity="1.0"/>
       <dynamics damping="0.1" friction="0.1"/>
     </joint>

     <joint name="link_1_to_2" type="revolute">
       <parent link="link_1"/>
       <child link="link_2"/>
       <origin xyz="0.13 0.0 0.065" rpy="1.57079632679 0.0 1.57079632679"/>
       <axis xyz="0.0 0.0 1.0"/>
       <limit lower="0" upper="3" effort="100.0" velocity="1.0"/>
       <dynamics damping="0.1" friction="0.1"/>
     </joint>

     <joint name="link_2_to_3" type="revolute">
       <parent link="link_2"/>
       <child link="link_3"/>
       <origin xyz="0.39 0.0 -0.13" rpy="3.14159265359 0.0 0.0"/>
       <axis xyz="0.0 0.0 1.0"/>
       <limit lower="-2" upper="2" effort="100.0" velocity="1.0"/>
       <dynamics damping="0.1" friction="0.1"/>
     </joint>

    <joint name="link_3_to_gripper" type="fixed">
       <parent link="link_3"/>
       <child link="gripper"/>
       <origin xyz="0.36 0.0 0.0" rpy="0.0 1.57079632679 0.0"/>
    </joint>
    <xacro:include filename="ros2controller_gazebo.xacro" />
</robot>